Workbook
Name Slicer_Category: #N/A
Name Slicer_MONTH: #N/A
Name Slicer_Payment_Mode: #N/A
Name Slicer_State: #N/A

Sheet Raw_Data (2)
A1: Order ID | B1: Order Date | C1: Customer Name | D1: City | E1: State | F1: Product | G1: Category | H1: Sales | I1: Quantity | J1: Discount | K1: Profit | L1: Payment Mode
A2: ORD-10001 | B2: 45658 | C2: Kavya Verma | D2: Ahmedabad | E2: Gujarat | F2: Monitor | G2: Electronics | H2: 53849.31 | I2: 5 | J2: 0.15 | K2: 10735.94 | L2: Debit Card
A3: ORD-10002 | B3: 45658.729 | C3: Vihaan Mehta | D3: Chennai | E3: Tamil Nadu | F3: Desk | G3: Furniture | H3: 55638.06 | I3: 5 | J3: 0.1 | K3: 4680.1 | L3: Cash
A4: ORD-10003 | B4: 45659.459 | C4: Isha Joshi | D4: Jaipur | E4: Rajasthan | F4: Smartphone | G4: Electronics | H4: 103172.43 | I4: 4 | J4: 0.05 | K4: 19081.87 | L4: UPI
A5: ORD-10004 | B5: 45660.188 | C5: Aditya Jain | D5: Chennai | E5: Tamil Nadu | F5: Backpack | G5: Accessories | H5: 2488.32 | I5: 2 | J5: 0.2 | K5: 314.91 | L5: Cash
A6: ORD-10005 | B6: 45660.918 | C6: Arjun Joshi | D6: Hyderabad | E6: Telangana | F6: Headphones | G6: Electronics | H6: 12903.29 | I6: 5 | J6: 0 | K6: 1200.14 | L6: Cash
A7: ORD-10006 | B7: 45661.647 | C7: Isha Jain | D7: Bhopal | E7: Madhya Pradesh | F7: Notebook | G7: Office Supplies | H7: 213.7 | I7: 1 | J7: 0 | K7: 27.4 | L7: Cash
A8: ORD-10007 | B8: 45662.377 | C8: Rahul Khan | D8: Bengaluru | E8: Karnataka | F8: Headphones | G8: Electronics | H8: 2087.17 | I8: 1 | J8: 0.1 | K8: 297.09 | L8: Credit Card
A9: ORD-10008 | B9: 45663.106 | C9: Arjun Mehta | D9: Pune | E9: Maharashtra | F9: Mouse | G9: Accessories | H9: 4363.85 | I9: 5 | J9: 0.15 | K9: 1169.07 | L9: Cash
A10: ORD-10009 | B10: 45663.836 | C10: Kavya Joshi | D10: Hyderabad | E10: Telangana | F10: Desk | G10: Furniture | H10: 55096.38 | I10: 5 | J10: 0.05 | K10: 13539.8 | L10: Cash
A11: ORD-10010 | B11: 45664.565 | C11: Neha Joshi | D11: Kolkata | E11: West Bengal | F11: Tablet | G11: Electronics | H11: 83427.92 | I11: 5 | J11: 0.15 | K11: 7918.15 | L11: UPI
A12: ORD-10011 | B12: 45665.295 | C12: Sneha Gupta | D12: Kolkata | E12: West Bengal | F12: Desk | G12: Furniture | H12: 29472.75 | I12: 3 | J12: 0.1 | K12: 7015.55 | L12: Credit Card
A13: ORD-10012 | B13: 45666.024 | C13: Aarav Jain | D13: Ahmedabad | E13: Gujarat | F13: Notebook | G13: Office Supplies | H13: 238.95 | I13: 1 | J13: 0.15 | K13: 40.6 | L13: Net Banking
... A26: ORD-10025 | B26: 45675.507 | C26: Kavya Verma | D26: Bengaluru | E26: Karnataka | F26: Laptop | G26: Electronics | H26: 157132.78 | I26: 3 | J26: 0 | K26: 41630.56 | L26: Cash
A27: ORD-10026 | B27: 45676.236 | D27: Lucknow | E27: Uttar Pradesh | F27: Printer | G27: Office Supplies | H27: 60533.71 | I27: 4 | J27: 0 | K27: 5969.87 | L27: Net Banking
A28: ORD-10027 | B28: 45676.966 | C28: Arjun Mehta | D28: Chennai | E28: Tamil Nadu | F28: Office Chair | G28: Furniture | H28: 7562.66 | I28: 1 | J28: 0.1 | K28: 1885.61 | L28: UPI
A29: ORD-10028 | B29: 45677.695 | C29: Aditya Joshi | D29: Bengaluru | E29: Karnataka | F29: Monitor | G29: Electronics | H29: 40365.65 | I29: 3 | J29: 0.15 | K29: 8630.08 | L29: Debit Card
A30: ORD-10029 | B30: 45678.425 | C30: Arjun Sharma | D30: Hyderabad | E30: Telangana | F30: Smartphone | G30: Electronics | H30: 56754 | I30: 2 | J30: 0.05 | K30: 15828.21 | L30: Cash
A31: ORD-10030 | B31: 45679.154 | C31: Aarav Verma | D31: Indore | E31: Madhya Pradesh | F31: Keyboard | G31: Accessories | H31: 6220.41 | I31: 4 | J31: 0.1 | K31: 1394.54 | L31: Net Banking
A32: ORD-10031 | B32: 45679.884 | C32: Aarav Gupta | D32: Mumbai | E32: Maharashtra | F32: Mouse | G32: Accessories | H32: 2514.52 | I32: 3 | J32: 0.05 | K32: 525.59 | L32: Cash
A33: ORD-10032 | B33: 45680.613 | C33: Rohan Khan | D33: Mumbai | E33: Maharashtra | F33: Monitor | G33: Electronics | H33: 45383.78 | I33: 3 | J33: 0 | K33: 12657.99 | L33: Debit Card
A34: ORD-10033 | B34: 45681.343 | C34: Aditya Sharma | D34: Kolkata | E34: West Bengal | F34: Printer | G34: Office Supplies | H34: 80405.31 | I34: 5 | J34: 0.05 | K34: 21977.26 | L34: Cash
A35: ORD-10034 | B35: 45682.072 | C35: Rahul Yadav | D35: Delhi | E35: Delhi | F35: Office Chair | G35: Furniture | H35: 8505.69 | I35: 1 | J35: 0 | K35: 1627.65 | L35: Debit Card
A36: ORD-10035 | B36: 45682.802 | C36: Sneha Yadav | D36: Bengaluru | E36: Karnataka | F36: Desk | G36: Furniture | H36: 19862.44 | I36: 2 | J36: 0.2 | K36: 2145.48 | L36: Credit Card
A37: ORD-10036 | B37: 45683.531 | C37: Kavya Jain | D37: Lucknow | E37: Uttar Pradesh | F37: Laptop | G37: Electronics | H37: 44103.82 | I37: 1 | J37: 0.1 | K37: 8404.6 | L37: Credit Card
A38: ORD-10037 | B38: 45684.261 | C38: Arjun Singh | D38: Mumbai | E38: Maharashtra | F38: Smartphone | G38: Electronics | H38: 31003.62 | I38: 1 | J38: 0 | K38: 2512.44 | L38: UPI
A39: ORD-10038 | B39: 45684.99 | C39: Neha Khan | D39: Bengaluru | E39: Karnataka | F39: Tablet | G39: Electronics | H39: 59652.68 | I39: 3 | J39: 0.05 | K39: 5893.47 | L39: Debit Card
... A321: ORD-10320 | B321: 45890.697 | C321: Aditya Khan | D321: Hyderabad | E321: Telangana | F321: Notebook | G321: Office Supplies | H321: 502.39 | I321: 2 | J321: 0.1 | K321: 90.65 | L321: UPI
A322: ORD-10321 | B322: 45891.427 | C322: Rahul Verma | D322: Hyderabad | E322: Telangana | F322: Office Chair | G322: Furniture | I322: 4 | J322: 0.1 | K322: 6665.69 | L322: Credit Card
A323: ORD-10322 | B323: 45892.156 | C323: Kavya Gupta | D323: Indore | E323: Madhya Pradesh | F323: Printer | G323: Office Supplies | H323: 53495.19 | I323: 4 | J323: 0.05 | K323: 10455.1 | L323: Net Banking
A324: ORD-10323 | B324: 45892.886 | C324: Arjun Verma | D324: Indore | E324: Madhya Pradesh | F324: Printer | G324: Office Supplies | H324: 12400.57 | I324: 1 | J324: 0.05 | K324: 3104.71 | L324: Net Banking
A325: ORD-10324 | B325: 45893.615 | C325: Aditya Verma | D325: Ahmedabad | E325: Gujarat | F325: Printer | G325: Office Supplies | H325: 74825.29 | I325: 5 | J325: 0.1 | K325: 9372.3 | L325: Cash
A326: ORD-10325 | B326: 45894.345 | C326: Arjun Sharma | D326: Kolkata | E326: West Bengal | F326: Printer | G326: Office Supplies | H326: 43804.2 | I326: 3 | J326: 0.05 | K326: 8770.25 | L326: Credit Card
A327: ORD-10326 | B327: 45895.074 | C327: Arjun Verma | D327: Bengaluru | E327: Karnataka | F327: Tablet | G327: Electronics | H327: 114809.44 | I327: 5 | J327: 0 | K327: 26679.57 | L327: Net Banking
A328: ORD-10327 | B328: 45895.804 | C328: Sneha Sharma | D328: Lucknow | E328: Uttar Pradesh | F328: Tablet | G328: Electronics | H328: 43516.75 | I328: 2 | J328: 0.05 | K328: 4105.47 | L328: UPI
A329: ORD-10328 | B329: 45896.533 | C329: Arjun Sharma | D329: Jaipur | E329: Rajasthan | F329: Keyboard | G329: Accessories | H329: 3572.15 | I329: 2 | J329: 0.1 | K329: 685.63 | L329: Net Banking
A330: ORD-10329 | B330: 45897.263 | C330: Rahul Yadav | D330: Bhopal | E330: Madhya Pradesh | F330: Keyboard | G330: Accessories | H330: 5451.7 | I330: 3 | J330: 0 | K330: 544.41 | L330: Debit Card
A331: ORD-10330 | B331: 45897.992 | C331: Kavya Gupta | D331: Bhopal | E331: Madhya Pradesh | F331: Mouse | G331: Accessories | H331: 2293.41 | I331: 3 | J331: 0.05 | K331: 243.12 | L331: Credit Card
A332: ORD-10331 | B332: 45898.721 | C332: Aarav Singh | D332: Kolkata | E332: West Bengal | F332: Keyboard | G332: Accessories | H332: 5426.29 | I332: 3 | J332: 0.1 | K332: 1331.29 | L332: UPI
A333: ORD-10332 | B333: 45899.451 | C333: Rahul Gupta | D333: Jaipur | E333: Rajasthan | F333: Monitor | G333: Electronics | H333: 56463.34 | I333: 5 | J333: 0.1 | K333: 10634.36 | L333: Debit Card
...

Sheet Pivot_Analysis
A3: Row Labels | B3: Sum of Sales | C3: Sum of Profit | D3: Count of Order ID
A4: 45658 | B4: 1714192.4 | C4: 334862.07 | D4: 43
A5: 45689 | B5: 1244194.4 | C5: 234146.57 | D5: 38
A6: 45717 | B6: 1427742.8 | C6: 259752.34 | D6: 43
A7: 45748 | B7: 1730810 | C7: 348608.4 | D7: 41
A8: 45778 | B8: 2189742.8 | C8: 394405.67 | D8: 43
A9: 45809 | B9: 1112397.9 | C9: 218721.74 | D9: 41
A10: 45839 | B10: 1687159.1 | C10: 283837.05 | D10: 42
A11: 45870 | B11: 1262631.2 | C11: 237703.89 | D11: 43
A12: 45901 | B12: 963699.98 | C12: 173122.69 | D12: 41
A13: 45931 | B13: 1129900.4 | C13: 194532.42 | D13: 42
A14: 45962 | B14: 1621642.1 | C14: 323728.09 | D14: 41
A15: 45992 | B15: 1473823.3 | C15: 227977.39 | D15: 42
A16: Grand Total | B16: 17557936 | C16: 3231398.3 | D16: 500
G17: ]

Sheet Category_Analysis
A3: Row Labels | B3: Sum of Profit
A4: Accessories | B4: 95943.01
A5: Electronics | B5: 2298256.9
A6: Furniture | B6: 408219.8
A7: Office Supplies | B7: 428978.66
A8: Grand Total | B8: 3231398.3

Sheet Product_Analysis
A3: Row Labels | B3: Sum of Sales
A4: Laptop | B4: 4403293.9
A5: Smartphone | B5: 3134954.7
A6: Tablet | B6: 2288679.1
A7: Printer | B7: 2261542.4
A8: Monitor | B8: 2177998.6
A9: Desk | B9: 1477105.4
A10: Office Chair | B10: 911375.98
A11: Headphones | B11: 366512.82
A12: Keyboard | B12: 256848.36
A13: Backpack | B13: 164309.67
A14: Grand Total | B14: 17442621

Sheet State_Analysis
A3: Row Labels | B3: Sum of Sales
A4: Delhi | B4: 1690873.5
A5: Gujarat | B5: 1186025.4
A6: Karnataka | B6: 2099078
A7: Madhya Pradesh | B7: 2267761.9
A8: Maharashtra | B8: 2836569.1
A9: Rajasthan | B9: 1171051
A10: Tamil Nadu | B10: 1181840.5
A11: Telangana | B11: 2054752.5
A12: Uttar Pradesh | B12: 1698000.4
A13: West Bengal | B13: 1371984.2
A14: Grand Total | B14: 17557936

Sheet Payment_Analysis
A3: Row Labels | B3: Sum of Sales
A4: Cash | B4: 3855465.8
A5: Credit Card | B5: 3655034.9
A6: Debit Card | B6: 3152191.1
A7: Net Banking | B7: 3608828
A8: UPI | B8: 3286416.7
A9: Grand Total | B9: 17557936

Sheet Discount_Analysis
A3: Row Labels | B3: Sum of Sales | C3: Sum of Profit | D3: Count of Order ID
A4: 0 | B4: 4609130.1 | C4: 883618.39 | D4: 122
A5: 0.05 | B5: 4370663.3 | C5: 778153.01 | D5: 129
A6: 0.1 | B6: 4685049.1 | C6: 871005.95 | D6: 125
A7: 0.15 | B7: 2873250 | C7: 510325.08 | D7: 77
A8: 0.2 | B8: 1010124.2 | C8: 186344.47 | D8: 46
A9: 0.25 | B9: 9719.67 | C9: 1951.42 | D9: 1
A10: Grand Total | B10: 17557936 | C10: 3231398.3 | D10: 500

Sheet Sheet10
A3: Row Labels | B3: Sum of Sales
A4: 45658 | B4: 1714192.4
A5: 45689 | B5: 1244194.4
A6: 45717 | B6: 1427742.8
A7: 45748 | B7: 1730810
A8: 45778 | B8: 2189742.8
A9: 45809 | B9: 1112397.9
A10: 45839 | B10: 1687159.1
A11: 45870 | B11: 1262631.2
A12: 45901 | B12: 963699.98
A13: 45931 | B13: 1129900.4
A14: 45962 | B14: 1621642.1
A15: 45992 | B15: 1473823.3
A16: Grand Total | B16: 17557936

Sheet Cleaned_Data
A1: Order ID | B1: Order Date | C1: Customer_Name | D1: City | E1: State | F1: Product | G1: Category | H1: Sales | I1: Quantity | J1: Discount | K1: Profit | L1: Payment_Mode | M1: MONTH
A2: ORD-10001 | B2: 45658 | C2: Kavya Verma | D2: Ahmedabad | E2: Gujarat | F2: Monitor | G2: Electronics | H2: 53849.31 | I2: 5 | J2: 0.15 | K2: 10735.94 | L2: Debit Card | M2: =DATE(YEAR(B2),MONTH(B2),1) -> 45658
A3: ORD-10002 | B3: 45658.729 | C3: Vihaan Mehta | D3: Chennai | E3: Tamil Nadu | F3: Desk | G3: Furniture | H3: 55638.06 | I3: 5 | J3: 0.1 | K3: 4680.1 | L3: Cash | M3: =DATE(YEAR(B3),MONTH(B3),1) -> 45658
A4: ORD-10003 | B4: 45659.459 | C4: Isha Joshi | D4: Jaipur | E4: Rajasthan | F4: Smartphone | G4: Electronics | H4: 103172.43 | I4: 4 | J4: 0.05 | K4: 19081.87 | L4: UPI | M4: =DATE(YEAR(B4),MONTH(B4),1) -> 45658
A5: ORD-10004 | B5: 45660.188 | C5: Aditya Jain | D5: Chennai | E5: Tamil Nadu | F5: Backpack | G5: Accessories | H5: 2488.32 | I5: 2 | J5: 0.2 | K5: 314.91 | L5: Cash | M5: =DATE(YEAR(B5),MONTH(B5),1) -> 45658
A6: ORD-10005 | B6: 45660.918 | C6: Arjun Joshi | D6: Hyderabad | E6: Telangana | F6: Headphones | G6: Electronics | H6: 12903.29 | I6: 5 | J6: 0 | K6: 1200.14 | L6: Cash | M6: =DATE(YEAR(B6),MONTH(B6),1) -> 45658
A7: ORD-10006 | B7: 45661.647 | C7: Isha Jain | D7: Bhopal | E7: Madhya Pradesh | F7: Notebook | G7: Office Supplies | H7: 213.7 | I7: 1 | J7: 0 | K7: 27.4 | L7: Cash | M7: =DATE(YEAR(B7),MONTH(B7),1) -> 45658
A8: ORD-10007 | B8: 45662.377 | C8: Rahul Khan | D8: Bengaluru | E8: Karnataka | F8: Headphones | G8: Electronics | H8: 2087.17 | I8: 1 | J8: 0.1 | K8: 297.09 | L8: Credit Card | M8: =DATE(YEAR(B8),MONTH(B8),1) -> 45658
A9: ORD-10008 | B9: 45663.106 | C9: Arjun Mehta | D9: Pune | E9: Maharashtra | F9: Mouse | G9: Accessories | H9: 4363.85 | I9: 5 | J9: 0.15 | K9: 1169.07 | L9: Cash | M9: =DATE(YEAR(B9),MONTH(B9),1) -> 45658
A10: ORD-10009 | B10: 45663.836 | C10: Kavya Joshi | D10: Hyderabad | E10: Telangana | F10: Desk | G10: Furniture | H10: 55096.38 | I10: 5 | J10: 0.05 | K10: 13539.8 | L10: Cash | M10: =DATE(YEAR(B10),MONTH(B10),1) -> 45658
A11: ORD-10010 | B11: 45664.565 | C11: Neha Joshi | D11: Kolkata | E11: West Bengal | F11: Tablet | G11: Electronics | H11: 83427.92 | I11: 5 | J11: 0.15 | K11: 7918.15 | L11: UPI | M11: =DATE(YEAR(B11),MONTH(B11),1) -> 45658
A12: ORD-10011 | B12: 45665.295 | C12: Sneha Gupta | D12: Kolkata | E12: West Bengal | F12: Desk | G12: Furniture | H12: 29472.75 | I12: 3 | J12: 0.1 | K12: 7015.55 | L12: Credit Card | M12: =DATE(YEAR(B12),MONTH(B12),1) -> 45658
A13: ORD-10012 | B13: 45666.024 | C13: Aarav Jain | D13: Ahmedabad | E13: Gujarat | F13: Notebook | G13: Office Supplies | H13: 238.95 | I13: 1 | J13: 0.15 | K13: 40.6 | L13: Net Banking | M13: =DATE(YEAR(B13),MONTH(B13),1) -> 45658
... A321: ORD-10320 | B321: 45890.697 | C321: Aditya Khan | D321: Hyderabad | E321: Telangana | F321: Notebook | G321: Office Supplies | H321: 502.39 | I321: 2 | J321: 0.1 | K321: 90.65 | L321: UPI | M321: =DATE(YEAR(B321),MONTH(B321),1) -> 45870
A322: ORD-10321 | B322: 45891.427 | C322: Rahul Verma | D322: Hyderabad | E322: Telangana | F322: Office Chair | G322: Furniture | I322: 4 | J322: 0.1 | K322: 6665.69 | L322: Credit Card | M322: =DATE(YEAR(B322),MONTH(B322),1) -> 45870
A323: ORD-10322 | B323: 45892.156 | C323: Kavya Gupta | D323: Indore | E323: Madhya Pradesh | F323: Printer | G323: Office Supplies | H323: 53495.19 | I323: 4 | J323: 0.05 | K323: 10455.1 | L323: Net Banking | M323: =DATE(YEAR(B323),MONTH(B323),1) -> 45870
A324: ORD-10323 | B324: 45892.886 | C324: Arjun Verma | D324: Indore | E324: Madhya Pradesh | F324: Printer | G324: Office Supplies | H324: 12400.57 | I324: 1 | J324: 0.05 | K324: 3104.71 | L324: Net Banking | M324: =DATE(YEAR(B324),MONTH(B324),1) -> 45870
A325: ORD-10324 | B325: 45893.615 | C325: Aditya Verma | D325: Ahmedabad | E325: Gujarat | F325: Printer | G325: Office Supplies | H325: 74825.29 | I325: 5 | J325: 0.1 | K325: 9372.3 | L325: Cash | M325: =DATE(YEAR(B325),MONTH(B325),1) -> 45870
A326: ORD-10325 | B326: 45894.345 | C326: Arjun Sharma | D326: Kolkata | E326: West Bengal | F326: Printer | G326: Office Supplies | H326: 43804.2 | I326: 3 | J326: 0.05 | K326: 8770.25 | L326: Credit Card | M326: =DATE(YEAR(B326),MONTH(B326),1) -> 45870
A327: ORD-10326 | B327: 45895.074 | C327: Arjun Verma | D327: Bengaluru | E327: Karnataka | F327: Tablet | G327: Electronics | H327: 114809.44 | I327: 5 | J327: 0 | K327: 26679.57 | L327: Net Banking | M327: =DATE(YEAR(B327),MONTH(B327),1) -> 45870
A328: ORD-10327 | B328: 45895.804 | C328: Sneha Sharma | D328: Lucknow | E328: Uttar Pradesh | F328: Tablet | G328: Electronics | H328: 43516.75 | I328: 2 | J328: 0.05 | K328: 4105.47 | L328: UPI | M328: =DATE(YEAR(B328),MONTH(B328),1) -> 45870
A329: ORD-10328 | B329: 45896.533 | C329: Arjun Sharma | D329: Jaipur | E329: Rajasthan | F329: Keyboard | G329: Accessories | H329: 3572.15 | I329: 2 | J329: 0.1 | K329: 685.63 | L329: Net Banking | M329: =DATE(YEAR(B329),MONTH(B329),1) -> 45870
A330: ORD-10329 | B330: 45897.263 | C330: Rahul Yadav | D330: Bhopal | E330: Madhya Pradesh | F330: Keyboard | G330: Accessories | H330: 5451.7 | I330: 3 | J330: 0 | K330: 544.41 | L330: Debit Card | M330: =DATE(YEAR(B330),MONTH(B330),1) -> 45870
A331: ORD-10330 | B331: 45897.992 | C331: Kavya Gupta | D331: Bhopal | E331: Madhya Pradesh | F331: Mouse | G331: Accessories | H331: 2293.41 | I331: 3 | J331: 0.05 | K331: 243.12 | L331: Credit Card | M331: =DATE(YEAR(B331),MONTH(B331),1) -> 45870
A332: ORD-10331 | B332: 45898.721 | C332: Aarav Singh | D332: Kolkata | E332: West Bengal | F332: Keyboard | G332: Accessories | H332: 5426.29 | I332: 3 | J332: 0.1 | K332: 1331.29 | L332: UPI | M332: =DATE(YEAR(B332),MONTH(B332),1) -> 45870
A333: ORD-10332 | B333: 45899.451 | C333: Rahul Gupta | D333: Jaipur | E333: Rajasthan | F333: Monitor | G333: Electronics | H333: 56463.34 | I333: 5 | J333: 0.1 | K333: 10634.36 | L333: Debit Card | M333: =DATE(YEAR(B333),MONTH(B333),1) -> 45870
A334: ORD-10333 | B334: 45900.18 | C334: Aarav Gupta | D334: Ahmedabad | E334: Gujarat | F334: Headphones | G334: Electronics | H334: 6702.49 | I334: 3 | J334: 0.05 | K334: 797.09 | L334: Cash | M334: =DATE(YEAR(B334),MONTH(B334),1) -> 45870
... A501: ORD-10500 | B501: 46022 | C501: Aditya Jain | D501: Hyderabad | E501: Telangana | F501: Printer | G501: Office Supplies | H501: 38562.59 | I501: 3 | J501: 0.05 | K501: 9266.17 | L501: Debit Card | M501: =DATE(YEAR(B501),MONTH(B501),1) -> 45992

Sheet Analysis
A1: Sales Performance Analysis
A3: KPI | B3: Value | D3: Month | E3: Sales | F3: Profit | G3: Orders
A4: Total Sales | B4: =SUM(SalesData[Sales]) -> 17557936 | D4: =IFERROR(INDEX(SalesData[MONTH],MATCH(0,COUNTIF($D$3:D3,SalesData[MONTH]),0)),"")
A5: Total Profit | B5: =SUM(SalesData[Profit]) -> 3231398.3
A6: Total Quantity | B6: =SUM(SalesData[Quantity]) -> 1533
A7: Total Orders | B7: =COUNTA(SalesData[Order ID]) -> 500
A8: Average Order Value | B8: =B4/B7 -> 35115.873
A9: Profit Margin | B9: =B5/B4 -> 0.18404203

Sheet Dashboard
A1: Sales Performance Dashboard
A4: Total Sales | C4: Total Profit | E4: Total Orders | G4: Total Quantity
A5: =Analysis!B4 -> 17557936 | C5: =Analysis!B5 -> 3231398.3 | E5: =Analysis!B7 -> 500 | G5: =Analysis!B6 -> 1533
A7: Average Order Value | C7: Profit Margin
A8: =Analysis!B8 -> 35115.873 | C8: =Analysis!B9 -> 0.18404203
